2025-03-22 22:30:42,835 - DataCollection - INFO - Initializing components...
2025-03-22 22:30:46,945 - elastic_transport.transport - INFO - HEAD http://localhost:9200/ [status:N/A duration:4.109s]
2025-03-22 22:30:46,946 - elastic_transport.node_pool - WARNING - Node <Urllib3HttpNode(http://localhost:9200)> has failed for 1 times in a row, putting on 1 second timeout
2025-03-22 22:30:46,946 - elastic_transport.transport - WARNING - Retrying request after failure (attempt 0 of 3)
Traceback (most recent call last):
  File "C:\Users\Saunav Barman\AppData\Local\Programs\Python\Python310\lib\site-packages\urllib3\connection.py", line 198, in _new_conn
    sock = connection.create_connection(
  File "C:\Users\Saunav Barman\AppData\Local\Programs\Python\Python310\lib\site-packages\urllib3\util\connection.py", line 85, in create_connection
    raise err
  File "C:\Users\Saunav Barman\AppData\Local\Programs\Python\Python310\lib\site-packages\urllib3\util\connection.py", line 73, in create_connection
    sock.connect(sa)
ConnectionRefusedError: [WinError 10061] No connection could be made because the target machine actively refused it

The above exception was the direct cause of the following exception:

Traceback (most recent call last):
  File "C:\Users\Saunav Barman\AppData\Local\Programs\Python\Python310\lib\site-packages\elastic_transport\_node\_http_urllib3.py", line 167, in perform_request
    response = self.pool.urlopen(
  File "C:\Users\Saunav Barman\AppData\Local\Programs\Python\Python310\lib\site-packages\urllib3\connectionpool.py", line 841, in urlopen
    retries = retries.increment(
  File "C:\Users\Saunav Barman\AppData\Local\Programs\Python\Python310\lib\site-packages\urllib3\util\retry.py", line 449, in increment
    raise reraise(type(error), error, _stacktrace)
  File "C:\Users\Saunav Barman\AppData\Local\Programs\Python\Python310\lib\site-packages\urllib3\util\util.py", line 39, in reraise
    raise value
  File "C:\Users\Saunav Barman\AppData\Local\Programs\Python\Python310\lib\site-packages\urllib3\connectionpool.py", line 787, in urlopen
    response = self._make_request(
  File "C:\Users\Saunav Barman\AppData\Local\Programs\Python\Python310\lib\site-packages\urllib3\connectionpool.py", line 493, in _make_request
    conn.request(
  File "C:\Users\Saunav Barman\AppData\Local\Programs\Python\Python310\lib\site-packages\urllib3\connection.py", line 445, in request
    self.endheaders()
  File "C:\Users\Saunav Barman\AppData\Local\Programs\Python\Python310\lib\http\client.py", line 1277, in endheaders
    self._send_output(message_body, encode_chunked=encode_chunked)
  File "C:\Users\Saunav Barman\AppData\Local\Programs\Python\Python310\lib\http\client.py", line 1037, in _send_output
    self.send(msg)
  File "C:\Users\Saunav Barman\AppData\Local\Programs\Python\Python310\lib\http\client.py", line 975, in send
    self.connect()
  File "C:\Users\Saunav Barman\AppData\Local\Programs\Python\Python310\lib\site-packages\urllib3\connection.py", line 276, in connect
    self.sock = self._new_conn()
  File "C:\Users\Saunav Barman\AppData\Local\Programs\Python\Python310\lib\site-packages\urllib3\connection.py", line 213, in _new_conn
    raise NewConnectionError(
urllib3.exceptions.NewConnectionError: <urllib3.connection.HTTPConnection object at 0x000001E13ECCB3D0>: Failed to establish a new connection: [WinError 10061] No connection could be made because the target machine actively refused it

The above exception was the direct cause of the following exception:

Traceback (most recent call last):
  File "C:\Users\Saunav Barman\AppData\Local\Programs\Python\Python310\lib\site-packages\elastic_transport\_transport.py", line 342, in perform_request
    resp = node.perform_request(
  File "C:\Users\Saunav Barman\AppData\Local\Programs\Python\Python310\lib\site-packages\elastic_transport\_node\_http_urllib3.py", line 202, in perform_request
    raise err from e
elastic_transport.ConnectionError: Connection error caused by: NewConnectionError(<urllib3.connection.HTTPConnection object at 0x000001E13ECCB3D0>: Failed to establish a new connection: [WinError 10061] No connection could be made because the target machine actively refused it)
2025-03-22 22:30:51,053 - elastic_transport.transport - INFO - HEAD http://localhost:9200/ [status:N/A duration:4.091s]
2025-03-22 22:30:51,053 - elastic_transport.node_pool - WARNING - Node <Urllib3HttpNode(http://localhost:9200)> has failed for 2 times in a row, putting on 2 second timeout
2025-03-22 22:30:51,055 - elastic_transport.transport - WARNING - Retrying request after failure (attempt 1 of 3)
Traceback (most recent call last):
  File "C:\Users\Saunav Barman\AppData\Local\Programs\Python\Python310\lib\site-packages\urllib3\connection.py", line 198, in _new_conn
    sock = connection.create_connection(
  File "C:\Users\Saunav Barman\AppData\Local\Programs\Python\Python310\lib\site-packages\urllib3\util\connection.py", line 85, in create_connection
    raise err
  File "C:\Users\Saunav Barman\AppData\Local\Programs\Python\Python310\lib\site-packages\urllib3\util\connection.py", line 73, in create_connection
    sock.connect(sa)
ConnectionRefusedError: [WinError 10061] No connection could be made because the target machine actively refused it

The above exception was the direct cause of the following exception:

Traceback (most recent call last):
  File "C:\Users\Saunav Barman\AppData\Local\Programs\Python\Python310\lib\site-packages\elastic_transport\_node\_http_urllib3.py", line 167, in perform_request
    response = self.pool.urlopen(
  File "C:\Users\Saunav Barman\AppData\Local\Programs\Python\Python310\lib\site-packages\urllib3\connectionpool.py", line 841, in urlopen
    retries = retries.increment(
  File "C:\Users\Saunav Barman\AppData\Local\Programs\Python\Python310\lib\site-packages\urllib3\util\retry.py", line 449, in increment
    raise reraise(type(error), error, _stacktrace)
  File "C:\Users\Saunav Barman\AppData\Local\Programs\Python\Python310\lib\site-packages\urllib3\util\util.py", line 39, in reraise
    raise value
  File "C:\Users\Saunav Barman\AppData\Local\Programs\Python\Python310\lib\site-packages\urllib3\connectionpool.py", line 787, in urlopen
    response = self._make_request(
  File "C:\Users\Saunav Barman\AppData\Local\Programs\Python\Python310\lib\site-packages\urllib3\connectionpool.py", line 493, in _make_request
    conn.request(
  File "C:\Users\Saunav Barman\AppData\Local\Programs\Python\Python310\lib\site-packages\urllib3\connection.py", line 445, in request
    self.endheaders()
  File "C:\Users\Saunav Barman\AppData\Local\Programs\Python\Python310\lib\http\client.py", line 1277, in endheaders
    self._send_output(message_body, encode_chunked=encode_chunked)
  File "C:\Users\Saunav Barman\AppData\Local\Programs\Python\Python310\lib\http\client.py", line 1037, in _send_output
    self.send(msg)
  File "C:\Users\Saunav Barman\AppData\Local\Programs\Python\Python310\lib\http\client.py", line 975, in send
    self.connect()
  File "C:\Users\Saunav Barman\AppData\Local\Programs\Python\Python310\lib\site-packages\urllib3\connection.py", line 276, in connect
    self.sock = self._new_conn()
  File "C:\Users\Saunav Barman\AppData\Local\Programs\Python\Python310\lib\site-packages\urllib3\connection.py", line 213, in _new_conn
    raise NewConnectionError(
urllib3.exceptions.NewConnectionError: <urllib3.connection.HTTPConnection object at 0x000001E13ECCB700>: Failed to establish a new connection: [WinError 10061] No connection could be made because the target machine actively refused it

The above exception was the direct cause of the following exception:

Traceback (most recent call last):
  File "C:\Users\Saunav Barman\AppData\Local\Programs\Python\Python310\lib\site-packages\elastic_transport\_transport.py", line 342, in perform_request
    resp = node.perform_request(
  File "C:\Users\Saunav Barman\AppData\Local\Programs\Python\Python310\lib\site-packages\elastic_transport\_node\_http_urllib3.py", line 202, in perform_request
    raise err from e
elastic_transport.ConnectionError: Connection error caused by: NewConnectionError(<urllib3.connection.HTTPConnection object at 0x000001E13ECCB700>: Failed to establish a new connection: [WinError 10061] No connection could be made because the target machine actively refused it)
2025-03-22 22:30:51,059 - elastic_transport.node_pool - INFO - Resurrected node <Urllib3HttpNode(http://localhost:9200)> (force=False)
2025-03-22 22:30:55,156 - elastic_transport.transport - INFO - HEAD http://localhost:9200/ [status:N/A duration:4.097s]
2025-03-22 22:30:55,158 - elastic_transport.node_pool - WARNING - Node <Urllib3HttpNode(http://localhost:9200)> has failed for 3 times in a row, putting on 4 second timeout
2025-03-22 22:30:55,158 - elastic_transport.transport - WARNING - Retrying request after failure (attempt 2 of 3)
Traceback (most recent call last):
  File "C:\Users\Saunav Barman\AppData\Local\Programs\Python\Python310\lib\site-packages\urllib3\connection.py", line 198, in _new_conn
    sock = connection.create_connection(
  File "C:\Users\Saunav Barman\AppData\Local\Programs\Python\Python310\lib\site-packages\urllib3\util\connection.py", line 85, in create_connection
    raise err
  File "C:\Users\Saunav Barman\AppData\Local\Programs\Python\Python310\lib\site-packages\urllib3\util\connection.py", line 73, in create_connection
    sock.connect(sa)
ConnectionRefusedError: [WinError 10061] No connection could be made because the target machine actively refused it

The above exception was the direct cause of the following exception:

Traceback (most recent call last):
  File "C:\Users\Saunav Barman\AppData\Local\Programs\Python\Python310\lib\site-packages\elastic_transport\_node\_http_urllib3.py", line 167, in perform_request
    response = self.pool.urlopen(
  File "C:\Users\Saunav Barman\AppData\Local\Programs\Python\Python310\lib\site-packages\urllib3\connectionpool.py", line 841, in urlopen
    retries = retries.increment(
  File "C:\Users\Saunav Barman\AppData\Local\Programs\Python\Python310\lib\site-packages\urllib3\util\retry.py", line 449, in increment
    raise reraise(type(error), error, _stacktrace)
  File "C:\Users\Saunav Barman\AppData\Local\Programs\Python\Python310\lib\site-packages\urllib3\util\util.py", line 39, in reraise
    raise value
  File "C:\Users\Saunav Barman\AppData\Local\Programs\Python\Python310\lib\site-packages\urllib3\connectionpool.py", line 787, in urlopen
    response = self._make_request(
  File "C:\Users\Saunav Barman\AppData\Local\Programs\Python\Python310\lib\site-packages\urllib3\connectionpool.py", line 493, in _make_request
    conn.request(
  File "C:\Users\Saunav Barman\AppData\Local\Programs\Python\Python310\lib\site-packages\urllib3\connection.py", line 445, in request
    self.endheaders()
  File "C:\Users\Saunav Barman\AppData\Local\Programs\Python\Python310\lib\http\client.py", line 1277, in endheaders
    self._send_output(message_body, encode_chunked=encode_chunked)
  File "C:\Users\Saunav Barman\AppData\Local\Programs\Python\Python310\lib\http\client.py", line 1037, in _send_output
    self.send(msg)
  File "C:\Users\Saunav Barman\AppData\Local\Programs\Python\Python310\lib\http\client.py", line 975, in send
    self.connect()
  File "C:\Users\Saunav Barman\AppData\Local\Programs\Python\Python310\lib\site-packages\urllib3\connection.py", line 276, in connect
    self.sock = self._new_conn()
  File "C:\Users\Saunav Barman\AppData\Local\Programs\Python\Python310\lib\site-packages\urllib3\connection.py", line 213, in _new_conn
    raise NewConnectionError(
urllib3.exceptions.NewConnectionError: <urllib3.connection.HTTPConnection object at 0x000001E13ECCB9D0>: Failed to establish a new connection: [WinError 10061] No connection could be made because the target machine actively refused it

The above exception was the direct cause of the following exception:

Traceback (most recent call last):
  File "C:\Users\Saunav Barman\AppData\Local\Programs\Python\Python310\lib\site-packages\elastic_transport\_transport.py", line 342, in perform_request
    resp = node.perform_request(
  File "C:\Users\Saunav Barman\AppData\Local\Programs\Python\Python310\lib\site-packages\elastic_transport\_node\_http_urllib3.py", line 202, in perform_request
    raise err from e
elastic_transport.ConnectionError: Connection error caused by: NewConnectionError(<urllib3.connection.HTTPConnection object at 0x000001E13ECCB9D0>: Failed to establish a new connection: [WinError 10061] No connection could be made because the target machine actively refused it)
2025-03-22 22:30:55,162 - elastic_transport.node_pool - INFO - Resurrected node <Urllib3HttpNode(http://localhost:9200)> (force=False)
2025-03-22 22:30:59,271 - elastic_transport.transport - INFO - HEAD http://localhost:9200/ [status:N/A duration:4.109s]
2025-03-22 22:30:59,272 - elastic_transport.node_pool - WARNING - Node <Urllib3HttpNode(http://localhost:9200)> has failed for 4 times in a row, putting on 8 second timeout
2025-03-22 22:30:59,272 - EventCollector - WARNING - Failed to connect to Elasticsearch: Connection error
2025-03-22 22:30:59,272 - EventCollector - INFO - Events will be stored in local file
2025-03-22 22:30:59,274 - IoTSimulation - INFO - Setting up network with 3 devices
2025-03-22 22:30:59,275 - IoTSimulation - INFO - Setting up device: camera_01 (SmartCamera)
2025-03-22 22:30:59,275 - IoTSimulation - INFO - Setting up device: lock_01 (SmartLock)
2025-03-22 22:30:59,275 - IoTSimulation - INFO - Setting up device: thermostat_01 (SmartThermostat)
2025-03-22 22:30:59,275 - IoTSimulation - INFO - Network setup completed successfully
2025-03-22 22:30:59,275 - IoTSimulation - INFO - Starting simulation
2025-03-22 22:30:59,276 - DataCollection - INFO - Letting network stabilize...
2025-03-22 22:31:29,285 - DataCollection - INFO - Collecting normal behavior data for 300 seconds
2025-03-22 22:36:29,772 - DataCollection - INFO - Simulating botnet attack
2025-03-22 22:36:29,773 - AttackSimulator - INFO - Launching botnet attack on targets: ['camera_01', 'lock_01']
2025-03-22 22:36:29,774 - AttackSimulator - INFO - Attack botnet_20250322_223629 launched successfully
2025-03-22 22:36:29,775 - DataCollection - INFO - 
Attack Status at 0.0s:
2025-03-22 22:36:29,775 - DataCollection - INFO - Status: in_progress
2025-03-22 22:36:29,775 - DataCollection - INFO - Events: 1 recorded
2025-03-22 22:36:34,782 - DataCollection - INFO - 
Attack Status at 5.0s:
2025-03-22 22:36:34,783 - DataCollection - INFO - Status: in_progress
2025-03-22 22:36:34,783 - DataCollection - INFO - Events: 5 recorded
2025-03-22 22:36:39,799 - DataCollection - INFO - 
Attack Status at 10.0s:
2025-03-22 22:36:39,799 - DataCollection - INFO - Status: in_progress
2025-03-22 22:36:39,801 - DataCollection - INFO - Events: 10 recorded
2025-03-22 22:36:44,810 - DataCollection - INFO - 
Attack Status at 15.0s:
2025-03-22 22:36:44,811 - DataCollection - INFO - Status: in_progress
2025-03-22 22:36:44,811 - DataCollection - INFO - Events: 15 recorded
2025-03-22 22:36:49,824 - DataCollection - INFO - 
Attack Status at 20.0s:
2025-03-22 22:36:49,824 - DataCollection - INFO - Status: in_progress
2025-03-22 22:36:49,825 - DataCollection - INFO - Events: 20 recorded
2025-03-22 22:36:54,841 - DataCollection - INFO - 
Attack Status at 25.1s:
2025-03-22 22:36:54,841 - DataCollection - INFO - Status: in_progress
2025-03-22 22:36:54,841 - DataCollection - INFO - Events: 25 recorded
2025-03-22 22:36:59,845 - DataCollection - INFO - 
Attack Status at 30.1s:
2025-03-22 22:36:59,846 - DataCollection - INFO - Status: in_progress
2025-03-22 22:36:59,846 - DataCollection - INFO - Events: 30 recorded
2025-03-22 22:37:04,848 - DataCollection - INFO - 
Attack Status at 35.1s:
2025-03-22 22:37:04,849 - DataCollection - INFO - Status: in_progress
2025-03-22 22:37:04,849 - DataCollection - INFO - Events: 35 recorded
2025-03-22 22:37:09,860 - DataCollection - INFO - 
Attack Status at 40.1s:
2025-03-22 22:37:09,860 - DataCollection - INFO - Status: in_progress
2025-03-22 22:37:09,860 - DataCollection - INFO - Events: 40 recorded
2025-03-22 22:37:14,870 - DataCollection - INFO - 
Attack Status at 45.1s:
2025-03-22 22:37:14,870 - DataCollection - INFO - Status: in_progress
2025-03-22 22:37:14,871 - DataCollection - INFO - Events: 45 recorded
2025-03-22 22:37:19,884 - DataCollection - INFO - 
Attack Status at 50.1s:
2025-03-22 22:37:19,884 - DataCollection - INFO - Status: in_progress
2025-03-22 22:37:19,884 - DataCollection - INFO - Events: 50 recorded
2025-03-22 22:37:24,886 - DataCollection - INFO - 
Attack Status at 55.1s:
2025-03-22 22:37:24,888 - DataCollection - INFO - Status: in_progress
2025-03-22 22:37:24,888 - DataCollection - INFO - Events: 55 recorded
2025-03-22 22:37:29,903 - DataCollection - INFO - 
Attack Status at 60.1s:
2025-03-22 22:37:29,904 - DataCollection - INFO - Status: in_progress
2025-03-22 22:37:29,904 - DataCollection - INFO - Events: 60 recorded
2025-03-22 22:37:34,911 - DataCollection - INFO - 
Attack Status at 65.1s:
2025-03-22 22:37:34,911 - DataCollection - INFO - Status: in_progress
2025-03-22 22:37:34,911 - DataCollection - INFO - Events: 65 recorded
2025-03-22 22:37:39,927 - DataCollection - INFO - 
Attack Status at 70.2s:
2025-03-22 22:37:39,927 - DataCollection - INFO - Status: in_progress
2025-03-22 22:37:39,927 - DataCollection - INFO - Events: 70 recorded
2025-03-22 22:37:44,953 - DataCollection - INFO - 
Attack Status at 75.2s:
2025-03-22 22:37:44,954 - DataCollection - INFO - Status: in_progress
2025-03-22 22:37:44,954 - DataCollection - INFO - Events: 75 recorded
2025-03-22 22:37:49,973 - DataCollection - INFO - 
Attack Status at 80.2s:
2025-03-22 22:37:49,974 - DataCollection - INFO - Status: in_progress
2025-03-22 22:37:49,974 - DataCollection - INFO - Events: 80 recorded
2025-03-22 22:37:54,984 - DataCollection - INFO - 
Attack Status at 85.2s:
2025-03-22 22:37:54,986 - DataCollection - INFO - Status: in_progress
2025-03-22 22:37:54,986 - DataCollection - INFO - Events: 85 recorded
2025-03-22 22:38:00,009 - DataCollection - INFO - 
Attack Status at 90.2s:
2025-03-22 22:38:00,010 - DataCollection - INFO - Status: in_progress
2025-03-22 22:38:00,010 - DataCollection - INFO - Events: 90 recorded
2025-03-22 22:38:05,020 - DataCollection - INFO - 
Attack Status at 95.2s:
2025-03-22 22:38:05,021 - DataCollection - INFO - Status: in_progress
2025-03-22 22:38:05,021 - DataCollection - INFO - Events: 95 recorded
2025-03-22 22:38:10,047 - DataCollection - INFO - 
Attack Status at 100.3s:
2025-03-22 22:38:10,048 - DataCollection - INFO - Status: in_progress
2025-03-22 22:38:10,048 - DataCollection - INFO - Events: 100 recorded
2025-03-22 22:38:15,060 - DataCollection - INFO - 
Attack Status at 105.3s:
2025-03-22 22:38:15,061 - DataCollection - INFO - Status: in_progress
2025-03-22 22:38:15,061 - DataCollection - INFO - Events: 105 recorded
2025-03-22 22:38:20,075 - DataCollection - INFO - 
Attack Status at 110.3s:
2025-03-22 22:38:20,075 - DataCollection - INFO - Status: in_progress
2025-03-22 22:38:20,076 - DataCollection - INFO - Events: 110 recorded
2025-03-22 22:38:25,092 - DataCollection - INFO - 
Attack Status at 115.3s:
2025-03-22 22:38:25,094 - DataCollection - INFO - Status: in_progress
2025-03-22 22:38:25,094 - DataCollection - INFO - Events: 115 recorded
2025-03-22 22:38:30,116 - DataCollection - INFO - 
Attack Status at 120.3s:
2025-03-22 22:38:30,117 - DataCollection - INFO - Status: in_progress
2025-03-22 22:38:30,117 - DataCollection - INFO - Events: 120 recorded
2025-03-22 22:38:35,135 - DataCollection - INFO - 
Attack Status at 125.4s:
2025-03-22 22:38:35,135 - DataCollection - INFO - Status: in_progress
2025-03-22 22:38:35,136 - DataCollection - INFO - Events: 125 recorded
2025-03-22 22:38:40,150 - DataCollection - INFO - 
Attack Status at 130.4s:
2025-03-22 22:38:40,151 - DataCollection - INFO - Status: in_progress
2025-03-22 22:38:40,151 - DataCollection - INFO - Events: 130 recorded
2025-03-22 22:38:45,166 - DataCollection - INFO - 
Attack Status at 135.4s:
2025-03-22 22:38:45,167 - DataCollection - INFO - Status: in_progress
2025-03-22 22:38:45,167 - DataCollection - INFO - Events: 134 recorded
2025-03-22 22:38:50,189 - DataCollection - INFO - 
Attack Status at 140.4s:
2025-03-22 22:38:50,190 - DataCollection - INFO - Status: in_progress
2025-03-22 22:38:50,190 - DataCollection - INFO - Events: 139 recorded
2025-03-22 22:38:55,197 - DataCollection - INFO - 
Attack Status at 145.4s:
2025-03-22 22:38:55,198 - DataCollection - INFO - Status: in_progress
2025-03-22 22:38:55,198 - DataCollection - INFO - Events: 144 recorded
2025-03-22 22:39:00,212 - DataCollection - INFO - 
Attack Status at 150.4s:
2025-03-22 22:39:00,213 - DataCollection - INFO - Status: in_progress
2025-03-22 22:39:00,213 - DataCollection - INFO - Events: 149 recorded
2025-03-22 22:39:05,235 - DataCollection - INFO - 
Attack Status at 155.5s:
2025-03-22 22:39:05,236 - DataCollection - INFO - Status: in_progress
2025-03-22 22:39:05,236 - DataCollection - INFO - Events: 154 recorded
2025-03-22 22:39:10,251 - DataCollection - INFO - 
Attack Status at 160.5s:
2025-03-22 22:39:10,252 - DataCollection - INFO - Status: in_progress
2025-03-22 22:39:10,252 - DataCollection - INFO - Events: 159 recorded
2025-03-22 22:39:15,255 - DataCollection - INFO - 
Attack Status at 165.5s:
2025-03-22 22:39:15,255 - DataCollection - INFO - Status: in_progress
2025-03-22 22:39:15,255 - DataCollection - INFO - Events: 164 recorded
2025-03-22 22:39:20,267 - DataCollection - INFO - 
Attack Status at 170.5s:
2025-03-22 22:39:20,268 - DataCollection - INFO - Status: in_progress
2025-03-22 22:39:20,268 - DataCollection - INFO - Events: 169 recorded
2025-03-22 22:39:25,288 - DataCollection - INFO - 
Attack Status at 175.5s:
2025-03-22 22:39:25,289 - DataCollection - INFO - Status: in_progress
2025-03-22 22:39:25,290 - DataCollection - INFO - Events: 174 recorded
2025-03-22 22:39:30,295 - DataCollection - INFO - Waiting for network recovery...
2025-03-22 22:40:00,306 - DataCollection - INFO - Simulating ddos attack
2025-03-22 22:40:00,306 - AttackSimulator - INFO - Launching ddos attack on targets: ['camera_01']
2025-03-22 22:40:00,308 - AttackSimulator - INFO - Attack ddos_20250322_224000 launched successfully
2025-03-22 22:40:00,309 - DataCollection - INFO - 
Attack Status at 0.0s:
2025-03-22 22:40:00,309 - DataCollection - INFO - Status: in_progress
2025-03-22 22:40:00,309 - DataCollection - INFO - Events: 1 recorded
2025-03-22 22:40:05,333 - DataCollection - INFO - 
Attack Status at 5.0s:
2025-03-22 22:40:05,333 - DataCollection - INFO - Status: in_progress
2025-03-22 22:40:05,334 - DataCollection - INFO - Events: 5 recorded
2025-03-22 22:40:10,349 - DataCollection - INFO - 
Attack Status at 10.0s:
2025-03-22 22:40:10,350 - DataCollection - INFO - Status: in_progress
2025-03-22 22:40:10,350 - DataCollection - INFO - Events: 10 recorded
2025-03-22 22:40:15,352 - DataCollection - INFO - 
Attack Status at 15.0s:
2025-03-22 22:40:15,354 - DataCollection - INFO - Status: in_progress
2025-03-22 22:40:15,354 - DataCollection - INFO - Events: 15 recorded
2025-03-22 22:40:20,363 - DataCollection - INFO - 
Attack Status at 20.1s:
2025-03-22 22:40:20,364 - DataCollection - INFO - Status: in_progress
2025-03-22 22:40:20,364 - DataCollection - INFO - Events: 20 recorded
2025-03-22 22:40:25,389 - DataCollection - INFO - 
Attack Status at 25.1s:
2025-03-22 22:40:25,390 - DataCollection - INFO - Status: in_progress
2025-03-22 22:40:25,390 - DataCollection - INFO - Events: 25 recorded
2025-03-22 22:40:30,409 - DataCollection - INFO - 
Attack Status at 30.1s:
2025-03-22 22:40:30,409 - DataCollection - INFO - Status: in_progress
2025-03-22 22:40:30,409 - DataCollection - INFO - Events: 30 recorded
2025-03-22 22:40:35,424 - DataCollection - INFO - 
Attack Status at 35.1s:
2025-03-22 22:40:35,425 - DataCollection - INFO - Status: in_progress
2025-03-22 22:40:35,425 - DataCollection - INFO - Events: 35 recorded
2025-03-22 22:40:40,448 - DataCollection - INFO - 
Attack Status at 40.1s:
2025-03-22 22:40:40,448 - DataCollection - INFO - Status: in_progress
2025-03-22 22:40:40,448 - DataCollection - INFO - Events: 40 recorded
2025-03-22 22:40:45,464 - DataCollection - INFO - 
Attack Status at 45.2s:
2025-03-22 22:40:45,464 - DataCollection - INFO - Status: in_progress
2025-03-22 22:40:45,465 - DataCollection - INFO - Events: 45 recorded
2025-03-22 22:40:50,468 - DataCollection - INFO - 
Attack Status at 50.2s:
2025-03-22 22:40:50,469 - DataCollection - INFO - Status: in_progress
2025-03-22 22:40:50,469 - DataCollection - INFO - Events: 50 recorded
2025-03-22 22:40:55,484 - DataCollection - INFO - 
Attack Status at 55.2s:
2025-03-22 22:40:55,484 - DataCollection - INFO - Status: in_progress
2025-03-22 22:40:55,484 - DataCollection - INFO - Events: 55 recorded
2025-03-22 22:41:00,500 - DataCollection - INFO - 
Attack Status at 60.2s:
2025-03-22 22:41:00,502 - DataCollection - INFO - Status: in_progress
2025-03-22 22:41:00,502 - DataCollection - INFO - Events: 60 recorded
2025-03-22 22:41:05,517 - DataCollection - INFO - 
Attack Status at 65.2s:
2025-03-22 22:41:05,517 - DataCollection - INFO - Status: in_progress
2025-03-22 22:41:05,517 - DataCollection - INFO - Events: 65 recorded
2025-03-22 22:41:10,539 - DataCollection - INFO - 
Attack Status at 70.2s:
2025-03-22 22:41:10,540 - DataCollection - INFO - Status: in_progress
2025-03-22 22:41:10,540 - DataCollection - INFO - Events: 70 recorded
2025-03-22 22:41:15,565 - DataCollection - INFO - 
Attack Status at 75.3s:
2025-03-22 22:41:15,566 - DataCollection - INFO - Status: in_progress
2025-03-22 22:41:15,566 - DataCollection - INFO - Events: 75 recorded
2025-03-22 22:41:20,583 - DataCollection - INFO - 
Attack Status at 80.3s:
2025-03-22 22:41:20,583 - DataCollection - INFO - Status: in_progress
2025-03-22 22:41:20,584 - DataCollection - INFO - Events: 80 recorded
2025-03-22 22:41:25,604 - DataCollection - INFO - 
Attack Status at 85.3s:
2025-03-22 22:41:25,605 - DataCollection - INFO - Status: in_progress
2025-03-22 22:41:25,605 - DataCollection - INFO - Events: 85 recorded
2025-03-22 22:41:29,876 - AttackSimulator - INFO - Attack botnet_20250322_223629 stopped successfully
2025-03-22 22:41:30,617 - DataCollection - INFO - 
Attack Status at 90.3s:
2025-03-22 22:41:30,618 - DataCollection - INFO - Status: in_progress
2025-03-22 22:41:30,618 - DataCollection - INFO - Events: 90 recorded
2025-03-22 22:41:35,631 - DataCollection - INFO - 
Attack Status at 95.3s:
2025-03-22 22:41:35,631 - DataCollection - INFO - Status: in_progress
2025-03-22 22:41:35,632 - DataCollection - INFO - Events: 95 recorded
2025-03-22 22:41:40,644 - DataCollection - INFO - 
Attack Status at 100.3s:
2025-03-22 22:41:40,645 - DataCollection - INFO - Status: in_progress
2025-03-22 22:41:40,645 - DataCollection - INFO - Events: 100 recorded
2025-03-22 22:41:45,657 - DataCollection - INFO - 
Attack Status at 105.3s:
2025-03-22 22:41:45,658 - DataCollection - INFO - Status: in_progress
2025-03-22 22:41:45,658 - DataCollection - INFO - Events: 105 recorded
2025-03-22 22:41:50,667 - DataCollection - INFO - 
Attack Status at 110.4s:
2025-03-22 22:41:50,668 - DataCollection - INFO - Status: in_progress
2025-03-22 22:41:50,668 - DataCollection - INFO - Events: 110 recorded
2025-03-22 22:41:55,670 - DataCollection - INFO - 
Attack Status at 115.4s:
2025-03-22 22:41:55,671 - DataCollection - INFO - Status: in_progress
2025-03-22 22:41:55,671 - DataCollection - INFO - Events: 115 recorded
2025-03-22 22:42:00,676 - DataCollection - INFO - Waiting for network recovery...
2025-03-22 22:42:30,682 - DataCollection - INFO - Simulating mitm attack
2025-03-22 22:42:30,682 - DataCollection - ERROR - Data collection failed: 'AttackSimulator' object has no attribute 'create_mitm_attack'
2025-03-22 22:42:30,682 - DataCollection - INFO - Stopping simulation...
2025-03-22 22:42:30,683 - IoTSimulation - INFO - Stopping simulation
2025-03-22 22:42:31,367 - DataCollection - INFO - Data collection completed
