2025-03-22 22:02:01,645 - DataCollection - INFO - Initializing components...
2025-03-22 22:02:05,732 - elastic_transport.transport - INFO - HEAD http://localhost:9200/ [status:N/A duration:4.085s]
2025-03-22 22:02:05,732 - elastic_transport.node_pool - WARNING - Node <Urllib3HttpNode(http://localhost:9200)> has failed for 1 times in a row, putting on 1 second timeout
2025-03-22 22:02:05,732 - elastic_transport.transport - WARNING - Retrying request after failure (attempt 0 of 3)
Traceback (most recent call last):
  File "C:\Users\Saunav Barman\AppData\Local\Programs\Python\Python310\lib\site-packages\urllib3\connection.py", line 198, in _new_conn
    sock = connection.create_connection(
  File "C:\Users\Saunav Barman\AppData\Local\Programs\Python\Python310\lib\site-packages\urllib3\util\connection.py", line 85, in create_connection
    raise err
  File "C:\Users\Saunav Barman\AppData\Local\Programs\Python\Python310\lib\site-packages\urllib3\util\connection.py", line 73, in create_connection
    sock.connect(sa)
ConnectionRefusedError: [WinError 10061] No connection could be made because the target machine actively refused it

The above exception was the direct cause of the following exception:

Traceback (most recent call last):
  File "C:\Users\Saunav Barman\AppData\Local\Programs\Python\Python310\lib\site-packages\elastic_transport\_node\_http_urllib3.py", line 167, in perform_request
    response = self.pool.urlopen(
  File "C:\Users\Saunav Barman\AppData\Local\Programs\Python\Python310\lib\site-packages\urllib3\connectionpool.py", line 841, in urlopen
    retries = retries.increment(
  File "C:\Users\Saunav Barman\AppData\Local\Programs\Python\Python310\lib\site-packages\urllib3\util\retry.py", line 449, in increment
    raise reraise(type(error), error, _stacktrace)
  File "C:\Users\Saunav Barman\AppData\Local\Programs\Python\Python310\lib\site-packages\urllib3\util\util.py", line 39, in reraise
    raise value
  File "C:\Users\Saunav Barman\AppData\Local\Programs\Python\Python310\lib\site-packages\urllib3\connectionpool.py", line 787, in urlopen
    response = self._make_request(
  File "C:\Users\Saunav Barman\AppData\Local\Programs\Python\Python310\lib\site-packages\urllib3\connectionpool.py", line 493, in _make_request
    conn.request(
  File "C:\Users\Saunav Barman\AppData\Local\Programs\Python\Python310\lib\site-packages\urllib3\connection.py", line 445, in request
    self.endheaders()
  File "C:\Users\Saunav Barman\AppData\Local\Programs\Python\Python310\lib\http\client.py", line 1277, in endheaders
    self._send_output(message_body, encode_chunked=encode_chunked)
  File "C:\Users\Saunav Barman\AppData\Local\Programs\Python\Python310\lib\http\client.py", line 1037, in _send_output
    self.send(msg)
  File "C:\Users\Saunav Barman\AppData\Local\Programs\Python\Python310\lib\http\client.py", line 975, in send
    self.connect()
  File "C:\Users\Saunav Barman\AppData\Local\Programs\Python\Python310\lib\site-packages\urllib3\connection.py", line 276, in connect
    self.sock = self._new_conn()
  File "C:\Users\Saunav Barman\AppData\Local\Programs\Python\Python310\lib\site-packages\urllib3\connection.py", line 213, in _new_conn
    raise NewConnectionError(
urllib3.exceptions.NewConnectionError: <urllib3.connection.HTTPConnection object at 0x00000199EFFBEFE0>: Failed to establish a new connection: [WinError 10061] No connection could be made because the target machine actively refused it

The above exception was the direct cause of the following exception:

Traceback (most recent call last):
  File "C:\Users\Saunav Barman\AppData\Local\Programs\Python\Python310\lib\site-packages\elastic_transport\_transport.py", line 342, in perform_request
    resp = node.perform_request(
  File "C:\Users\Saunav Barman\AppData\Local\Programs\Python\Python310\lib\site-packages\elastic_transport\_node\_http_urllib3.py", line 202, in perform_request
    raise err from e
elastic_transport.ConnectionError: Connection error caused by: NewConnectionError(<urllib3.connection.HTTPConnection object at 0x00000199EFFBEFE0>: Failed to establish a new connection: [WinError 10061] No connection could be made because the target machine actively refused it)
2025-03-22 22:02:09,863 - elastic_transport.transport - INFO - HEAD http://localhost:9200/ [status:N/A duration:4.094s]
2025-03-22 22:02:09,863 - elastic_transport.node_pool - WARNING - Node <Urllib3HttpNode(http://localhost:9200)> has failed for 2 times in a row, putting on 2 second timeout
2025-03-22 22:02:09,864 - elastic_transport.transport - WARNING - Retrying request after failure (attempt 1 of 3)
Traceback (most recent call last):
  File "C:\Users\Saunav Barman\AppData\Local\Programs\Python\Python310\lib\site-packages\urllib3\connection.py", line 198, in _new_conn
    sock = connection.create_connection(
  File "C:\Users\Saunav Barman\AppData\Local\Programs\Python\Python310\lib\site-packages\urllib3\util\connection.py", line 85, in create_connection
    raise err
  File "C:\Users\Saunav Barman\AppData\Local\Programs\Python\Python310\lib\site-packages\urllib3\util\connection.py", line 73, in create_connection
    sock.connect(sa)
ConnectionRefusedError: [WinError 10061] No connection could be made because the target machine actively refused it

The above exception was the direct cause of the following exception:

Traceback (most recent call last):
  File "C:\Users\Saunav Barman\AppData\Local\Programs\Python\Python310\lib\site-packages\elastic_transport\_node\_http_urllib3.py", line 167, in perform_request
    response = self.pool.urlopen(
  File "C:\Users\Saunav Barman\AppData\Local\Programs\Python\Python310\lib\site-packages\urllib3\connectionpool.py", line 841, in urlopen
    retries = retries.increment(
  File "C:\Users\Saunav Barman\AppData\Local\Programs\Python\Python310\lib\site-packages\urllib3\util\retry.py", line 449, in increment
    raise reraise(type(error), error, _stacktrace)
  File "C:\Users\Saunav Barman\AppData\Local\Programs\Python\Python310\lib\site-packages\urllib3\util\util.py", line 39, in reraise
    raise value
  File "C:\Users\Saunav Barman\AppData\Local\Programs\Python\Python310\lib\site-packages\urllib3\connectionpool.py", line 787, in urlopen
    response = self._make_request(
  File "C:\Users\Saunav Barman\AppData\Local\Programs\Python\Python310\lib\site-packages\urllib3\connectionpool.py", line 493, in _make_request
    conn.request(
  File "C:\Users\Saunav Barman\AppData\Local\Programs\Python\Python310\lib\site-packages\urllib3\connection.py", line 445, in request
    self.endheaders()
  File "C:\Users\Saunav Barman\AppData\Local\Programs\Python\Python310\lib\http\client.py", line 1277, in endheaders
    self._send_output(message_body, encode_chunked=encode_chunked)
  File "C:\Users\Saunav Barman\AppData\Local\Programs\Python\Python310\lib\http\client.py", line 1037, in _send_output
    self.send(msg)
  File "C:\Users\Saunav Barman\AppData\Local\Programs\Python\Python310\lib\http\client.py", line 975, in send
    self.connect()
  File "C:\Users\Saunav Barman\AppData\Local\Programs\Python\Python310\lib\site-packages\urllib3\connection.py", line 276, in connect
    self.sock = self._new_conn()
  File "C:\Users\Saunav Barman\AppData\Local\Programs\Python\Python310\lib\site-packages\urllib3\connection.py", line 213, in _new_conn
    raise NewConnectionError(
urllib3.exceptions.NewConnectionError: <urllib3.connection.HTTPConnection object at 0x00000199EFFBF310>: Failed to establish a new connection: [WinError 10061] No connection could be made because the target machine actively refused it

The above exception was the direct cause of the following exception:

Traceback (most recent call last):
  File "C:\Users\Saunav Barman\AppData\Local\Programs\Python\Python310\lib\site-packages\elastic_transport\_transport.py", line 342, in perform_request
    resp = node.perform_request(
  File "C:\Users\Saunav Barman\AppData\Local\Programs\Python\Python310\lib\site-packages\elastic_transport\_node\_http_urllib3.py", line 202, in perform_request
    raise err from e
elastic_transport.ConnectionError: Connection error caused by: NewConnectionError(<urllib3.connection.HTTPConnection object at 0x00000199EFFBF310>: Failed to establish a new connection: [WinError 10061] No connection could be made because the target machine actively refused it)
2025-03-22 22:02:09,867 - elastic_transport.node_pool - INFO - Resurrected node <Urllib3HttpNode(http://localhost:9200)> (force=False)
2025-03-22 22:02:13,971 - elastic_transport.transport - INFO - HEAD http://localhost:9200/ [status:N/A duration:4.103s]
2025-03-22 22:02:13,971 - elastic_transport.node_pool - WARNING - Node <Urllib3HttpNode(http://localhost:9200)> has failed for 3 times in a row, putting on 4 second timeout
2025-03-22 22:02:13,972 - elastic_transport.transport - WARNING - Retrying request after failure (attempt 2 of 3)
Traceback (most recent call last):
  File "C:\Users\Saunav Barman\AppData\Local\Programs\Python\Python310\lib\site-packages\urllib3\connection.py", line 198, in _new_conn
    sock = connection.create_connection(
  File "C:\Users\Saunav Barman\AppData\Local\Programs\Python\Python310\lib\site-packages\urllib3\util\connection.py", line 85, in create_connection
    raise err
  File "C:\Users\Saunav Barman\AppData\Local\Programs\Python\Python310\lib\site-packages\urllib3\util\connection.py", line 73, in create_connection
    sock.connect(sa)
ConnectionRefusedError: [WinError 10061] No connection could be made because the target machine actively refused it

The above exception was the direct cause of the following exception:

Traceback (most recent call last):
  File "C:\Users\Saunav Barman\AppData\Local\Programs\Python\Python310\lib\site-packages\elastic_transport\_node\_http_urllib3.py", line 167, in perform_request
    response = self.pool.urlopen(
  File "C:\Users\Saunav Barman\AppData\Local\Programs\Python\Python310\lib\site-packages\urllib3\connectionpool.py", line 841, in urlopen
    retries = retries.increment(
  File "C:\Users\Saunav Barman\AppData\Local\Programs\Python\Python310\lib\site-packages\urllib3\util\retry.py", line 449, in increment
    raise reraise(type(error), error, _stacktrace)
  File "C:\Users\Saunav Barman\AppData\Local\Programs\Python\Python310\lib\site-packages\urllib3\util\util.py", line 39, in reraise
    raise value
  File "C:\Users\Saunav Barman\AppData\Local\Programs\Python\Python310\lib\site-packages\urllib3\connectionpool.py", line 787, in urlopen
    response = self._make_request(
  File "C:\Users\Saunav Barman\AppData\Local\Programs\Python\Python310\lib\site-packages\urllib3\connectionpool.py", line 493, in _make_request
    conn.request(
  File "C:\Users\Saunav Barman\AppData\Local\Programs\Python\Python310\lib\site-packages\urllib3\connection.py", line 445, in request
    self.endheaders()
  File "C:\Users\Saunav Barman\AppData\Local\Programs\Python\Python310\lib\http\client.py", line 1277, in endheaders
    self._send_output(message_body, encode_chunked=encode_chunked)
  File "C:\Users\Saunav Barman\AppData\Local\Programs\Python\Python310\lib\http\client.py", line 1037, in _send_output
    self.send(msg)
  File "C:\Users\Saunav Barman\AppData\Local\Programs\Python\Python310\lib\http\client.py", line 975, in send
    self.connect()
  File "C:\Users\Saunav Barman\AppData\Local\Programs\Python\Python310\lib\site-packages\urllib3\connection.py", line 276, in connect
    self.sock = self._new_conn()
  File "C:\Users\Saunav Barman\AppData\Local\Programs\Python\Python310\lib\site-packages\urllib3\connection.py", line 213, in _new_conn
    raise NewConnectionError(
urllib3.exceptions.NewConnectionError: <urllib3.connection.HTTPConnection object at 0x00000199EFFBF5E0>: Failed to establish a new connection: [WinError 10061] No connection could be made because the target machine actively refused it

The above exception was the direct cause of the following exception:

Traceback (most recent call last):
  File "C:\Users\Saunav Barman\AppData\Local\Programs\Python\Python310\lib\site-packages\elastic_transport\_transport.py", line 342, in perform_request
    resp = node.perform_request(
  File "C:\Users\Saunav Barman\AppData\Local\Programs\Python\Python310\lib\site-packages\elastic_transport\_node\_http_urllib3.py", line 202, in perform_request
    raise err from e
elastic_transport.ConnectionError: Connection error caused by: NewConnectionError(<urllib3.connection.HTTPConnection object at 0x00000199EFFBF5E0>: Failed to establish a new connection: [WinError 10061] No connection could be made because the target machine actively refused it)
2025-03-22 22:02:13,976 - elastic_transport.node_pool - INFO - Resurrected node <Urllib3HttpNode(http://localhost:9200)> (force=False)
2025-03-22 22:02:18,040 - elastic_transport.transport - INFO - HEAD http://localhost:9200/ [status:N/A duration:4.065s]
2025-03-22 22:02:18,040 - elastic_transport.node_pool - WARNING - Node <Urllib3HttpNode(http://localhost:9200)> has failed for 4 times in a row, putting on 8 second timeout
2025-03-22 22:02:18,041 - EventCollector - WARNING - Failed to connect to Elasticsearch: Connection error
2025-03-22 22:02:18,041 - EventCollector - INFO - Events will be stored in local file
2025-03-22 22:02:18,043 - IoTSimulation - INFO - Setting up network with 3 devices
2025-03-22 22:02:18,044 - IoTSimulation - INFO - Setting up device: camera_01 (SmartCamera)
2025-03-22 22:02:18,044 - IoTSimulation - INFO - Setting up device: lock_01 (SmartLock)
2025-03-22 22:02:18,044 - IoTSimulation - INFO - Setting up device: thermostat_01 (SmartThermostat)
2025-03-22 22:02:18,044 - IoTSimulation - INFO - Network setup completed successfully
2025-03-22 22:02:18,045 - IoTSimulation - INFO - Starting simulation
2025-03-22 22:02:18,047 - DataCollection - INFO - Letting network stabilize...
2025-03-22 22:02:48,051 - DataCollection - INFO - Collecting normal behavior data for 300 seconds
2025-03-22 22:07:48,521 - DataCollection - INFO - Simulating botnet attack
2025-03-22 22:07:48,521 - DataCollection - ERROR - Data collection failed: 'AttackSimulator' object has no attribute 'create_attack'
2025-03-22 22:07:48,521 - DataCollection - INFO - Stopping simulation...
2025-03-22 22:07:48,521 - IoTSimulation - INFO - Stopping simulation
2025-03-22 22:07:49,374 - DataCollection - INFO - Data collection completed
