2025-03-23 20:48:57,269 - elastic_transport.transport - INFO - HEAD http://localhost:9200/ [status:N/A duration:4.123s]
2025-03-23 20:48:57,271 - elastic_transport.node_pool - WARNING - Node <Urllib3HttpNode(http://localhost:9200)> has failed for 1 times in a row, putting on 1 second timeout
2025-03-23 20:48:57,271 - elastic_transport.transport - WARNING - Retrying request after failure (attempt 0 of 3)
Traceback (most recent call last):
  File "C:\Users\Saunav Barman\AppData\Local\Programs\Python\Python310\lib\site-packages\urllib3\connection.py", line 198, in _new_conn
    sock = connection.create_connection(
  File "C:\Users\Saunav Barman\AppData\Local\Programs\Python\Python310\lib\site-packages\urllib3\util\connection.py", line 85, in create_connection
    raise err
  File "C:\Users\Saunav Barman\AppData\Local\Programs\Python\Python310\lib\site-packages\urllib3\util\connection.py", line 73, in create_connection
    sock.connect(sa)
ConnectionRefusedError: [WinError 10061] No connection could be made because the target machine actively refused it

The above exception was the direct cause of the following exception:

Traceback (most recent call last):
  File "C:\Users\Saunav Barman\AppData\Local\Programs\Python\Python310\lib\site-packages\elastic_transport\_node\_http_urllib3.py", line 167, in perform_request
    response = self.pool.urlopen(
  File "C:\Users\Saunav Barman\AppData\Local\Programs\Python\Python310\lib\site-packages\urllib3\connectionpool.py", line 841, in urlopen
    retries = retries.increment(
  File "C:\Users\Saunav Barman\AppData\Local\Programs\Python\Python310\lib\site-packages\urllib3\util\retry.py", line 449, in increment
    raise reraise(type(error), error, _stacktrace)
  File "C:\Users\Saunav Barman\AppData\Local\Programs\Python\Python310\lib\site-packages\urllib3\util\util.py", line 39, in reraise
    raise value
  File "C:\Users\Saunav Barman\AppData\Local\Programs\Python\Python310\lib\site-packages\urllib3\connectionpool.py", line 787, in urlopen
    response = self._make_request(
  File "C:\Users\Saunav Barman\AppData\Local\Programs\Python\Python310\lib\site-packages\urllib3\connectionpool.py", line 493, in _make_request
    conn.request(
  File "C:\Users\Saunav Barman\AppData\Local\Programs\Python\Python310\lib\site-packages\urllib3\connection.py", line 445, in request
    self.endheaders()
  File "C:\Users\Saunav Barman\AppData\Local\Programs\Python\Python310\lib\http\client.py", line 1277, in endheaders
    self._send_output(message_body, encode_chunked=encode_chunked)
  File "C:\Users\Saunav Barman\AppData\Local\Programs\Python\Python310\lib\http\client.py", line 1037, in _send_output
    self.send(msg)
  File "C:\Users\Saunav Barman\AppData\Local\Programs\Python\Python310\lib\http\client.py", line 975, in send
    self.connect()
  File "C:\Users\Saunav Barman\AppData\Local\Programs\Python\Python310\lib\site-packages\urllib3\connection.py", line 276, in connect
    self.sock = self._new_conn()
  File "C:\Users\Saunav Barman\AppData\Local\Programs\Python\Python310\lib\site-packages\urllib3\connection.py", line 213, in _new_conn
    raise NewConnectionError(
urllib3.exceptions.NewConnectionError: <urllib3.connection.HTTPConnection object at 0x00000183109FCD00>: Failed to establish a new connection: [WinError 10061] No connection could be made because the target machine actively refused it

The above exception was the direct cause of the following exception:

Traceback (most recent call last):
  File "C:\Users\Saunav Barman\AppData\Local\Programs\Python\Python310\lib\site-packages\elastic_transport\_transport.py", line 342, in perform_request
    resp = node.perform_request(
  File "C:\Users\Saunav Barman\AppData\Local\Programs\Python\Python310\lib\site-packages\elastic_transport\_node\_http_urllib3.py", line 202, in perform_request
    raise err from e
elastic_transport.ConnectionError: Connection error caused by: NewConnectionError(<urllib3.connection.HTTPConnection object at 0x00000183109FCD00>: Failed to establish a new connection: [WinError 10061] No connection could be made because the target machine actively refused it)
2025-03-23 20:49:01,389 - elastic_transport.transport - INFO - HEAD http://localhost:9200/ [status:N/A duration:4.100s]
2025-03-23 20:49:01,390 - elastic_transport.node_pool - WARNING - Node <Urllib3HttpNode(http://localhost:9200)> has failed for 2 times in a row, putting on 2 second timeout
2025-03-23 20:49:01,390 - elastic_transport.transport - WARNING - Retrying request after failure (attempt 1 of 3)
Traceback (most recent call last):
  File "C:\Users\Saunav Barman\AppData\Local\Programs\Python\Python310\lib\site-packages\urllib3\connection.py", line 198, in _new_conn
    sock = connection.create_connection(
  File "C:\Users\Saunav Barman\AppData\Local\Programs\Python\Python310\lib\site-packages\urllib3\util\connection.py", line 85, in create_connection
    raise err
  File "C:\Users\Saunav Barman\AppData\Local\Programs\Python\Python310\lib\site-packages\urllib3\util\connection.py", line 73, in create_connection
    sock.connect(sa)
ConnectionRefusedError: [WinError 10061] No connection could be made because the target machine actively refused it

The above exception was the direct cause of the following exception:

Traceback (most recent call last):
  File "C:\Users\Saunav Barman\AppData\Local\Programs\Python\Python310\lib\site-packages\elastic_transport\_node\_http_urllib3.py", line 167, in perform_request
    response = self.pool.urlopen(
  File "C:\Users\Saunav Barman\AppData\Local\Programs\Python\Python310\lib\site-packages\urllib3\connectionpool.py", line 841, in urlopen
    retries = retries.increment(
  File "C:\Users\Saunav Barman\AppData\Local\Programs\Python\Python310\lib\site-packages\urllib3\util\retry.py", line 449, in increment
    raise reraise(type(error), error, _stacktrace)
  File "C:\Users\Saunav Barman\AppData\Local\Programs\Python\Python310\lib\site-packages\urllib3\util\util.py", line 39, in reraise
    raise value
  File "C:\Users\Saunav Barman\AppData\Local\Programs\Python\Python310\lib\site-packages\urllib3\connectionpool.py", line 787, in urlopen
    response = self._make_request(
  File "C:\Users\Saunav Barman\AppData\Local\Programs\Python\Python310\lib\site-packages\urllib3\connectionpool.py", line 493, in _make_request
    conn.request(
  File "C:\Users\Saunav Barman\AppData\Local\Programs\Python\Python310\lib\site-packages\urllib3\connection.py", line 445, in request
    self.endheaders()
  File "C:\Users\Saunav Barman\AppData\Local\Programs\Python\Python310\lib\http\client.py", line 1277, in endheaders
    self._send_output(message_body, encode_chunked=encode_chunked)
  File "C:\Users\Saunav Barman\AppData\Local\Programs\Python\Python310\lib\http\client.py", line 1037, in _send_output
    self.send(msg)
  File "C:\Users\Saunav Barman\AppData\Local\Programs\Python\Python310\lib\http\client.py", line 975, in send
    self.connect()
  File "C:\Users\Saunav Barman\AppData\Local\Programs\Python\Python310\lib\site-packages\urllib3\connection.py", line 276, in connect
    self.sock = self._new_conn()
  File "C:\Users\Saunav Barman\AppData\Local\Programs\Python\Python310\lib\site-packages\urllib3\connection.py", line 213, in _new_conn
    raise NewConnectionError(
urllib3.exceptions.NewConnectionError: <urllib3.connection.HTTPConnection object at 0x00000183109FCF10>: Failed to establish a new connection: [WinError 10061] No connection could be made because the target machine actively refused it

The above exception was the direct cause of the following exception:

Traceback (most recent call last):
  File "C:\Users\Saunav Barman\AppData\Local\Programs\Python\Python310\lib\site-packages\elastic_transport\_transport.py", line 342, in perform_request
    resp = node.perform_request(
  File "C:\Users\Saunav Barman\AppData\Local\Programs\Python\Python310\lib\site-packages\elastic_transport\_node\_http_urllib3.py", line 202, in perform_request
    raise err from e
elastic_transport.ConnectionError: Connection error caused by: NewConnectionError(<urllib3.connection.HTTPConnection object at 0x00000183109FCF10>: Failed to establish a new connection: [WinError 10061] No connection could be made because the target machine actively refused it)
2025-03-23 20:49:01,395 - elastic_transport.node_pool - INFO - Resurrected node <Urllib3HttpNode(http://localhost:9200)> (force=False)
2025-03-23 20:49:05,496 - elastic_transport.transport - INFO - HEAD http://localhost:9200/ [status:N/A duration:4.100s]
2025-03-23 20:49:05,496 - elastic_transport.node_pool - WARNING - Node <Urllib3HttpNode(http://localhost:9200)> has failed for 3 times in a row, putting on 4 second timeout
2025-03-23 20:49:05,497 - elastic_transport.transport - WARNING - Retrying request after failure (attempt 2 of 3)
Traceback (most recent call last):
  File "C:\Users\Saunav Barman\AppData\Local\Programs\Python\Python310\lib\site-packages\urllib3\connection.py", line 198, in _new_conn
    sock = connection.create_connection(
  File "C:\Users\Saunav Barman\AppData\Local\Programs\Python\Python310\lib\site-packages\urllib3\util\connection.py", line 85, in create_connection
    raise err
  File "C:\Users\Saunav Barman\AppData\Local\Programs\Python\Python310\lib\site-packages\urllib3\util\connection.py", line 73, in create_connection
    sock.connect(sa)
ConnectionRefusedError: [WinError 10061] No connection could be made because the target machine actively refused it

The above exception was the direct cause of the following exception:

Traceback (most recent call last):
  File "C:\Users\Saunav Barman\AppData\Local\Programs\Python\Python310\lib\site-packages\elastic_transport\_node\_http_urllib3.py", line 167, in perform_request
    response = self.pool.urlopen(
  File "C:\Users\Saunav Barman\AppData\Local\Programs\Python\Python310\lib\site-packages\urllib3\connectionpool.py", line 841, in urlopen
    retries = retries.increment(
  File "C:\Users\Saunav Barman\AppData\Local\Programs\Python\Python310\lib\site-packages\urllib3\util\retry.py", line 449, in increment
    raise reraise(type(error), error, _stacktrace)
  File "C:\Users\Saunav Barman\AppData\Local\Programs\Python\Python310\lib\site-packages\urllib3\util\util.py", line 39, in reraise
    raise value
  File "C:\Users\Saunav Barman\AppData\Local\Programs\Python\Python310\lib\site-packages\urllib3\connectionpool.py", line 787, in urlopen
    response = self._make_request(
  File "C:\Users\Saunav Barman\AppData\Local\Programs\Python\Python310\lib\site-packages\urllib3\connectionpool.py", line 493, in _make_request
    conn.request(
  File "C:\Users\Saunav Barman\AppData\Local\Programs\Python\Python310\lib\site-packages\urllib3\connection.py", line 445, in request
    self.endheaders()
  File "C:\Users\Saunav Barman\AppData\Local\Programs\Python\Python310\lib\http\client.py", line 1277, in endheaders
    self._send_output(message_body, encode_chunked=encode_chunked)
  File "C:\Users\Saunav Barman\AppData\Local\Programs\Python\Python310\lib\http\client.py", line 1037, in _send_output
    self.send(msg)
  File "C:\Users\Saunav Barman\AppData\Local\Programs\Python\Python310\lib\http\client.py", line 975, in send
    self.connect()
  File "C:\Users\Saunav Barman\AppData\Local\Programs\Python\Python310\lib\site-packages\urllib3\connection.py", line 276, in connect
    self.sock = self._new_conn()
  File "C:\Users\Saunav Barman\AppData\Local\Programs\Python\Python310\lib\site-packages\urllib3\connection.py", line 213, in _new_conn
    raise NewConnectionError(
urllib3.exceptions.NewConnectionError: <urllib3.connection.HTTPConnection object at 0x00000183109FD150>: Failed to establish a new connection: [WinError 10061] No connection could be made because the target machine actively refused it

The above exception was the direct cause of the following exception:

Traceback (most recent call last):
  File "C:\Users\Saunav Barman\AppData\Local\Programs\Python\Python310\lib\site-packages\elastic_transport\_transport.py", line 342, in perform_request
    resp = node.perform_request(
  File "C:\Users\Saunav Barman\AppData\Local\Programs\Python\Python310\lib\site-packages\elastic_transport\_node\_http_urllib3.py", line 202, in perform_request
    raise err from e
elastic_transport.ConnectionError: Connection error caused by: NewConnectionError(<urllib3.connection.HTTPConnection object at 0x00000183109FD150>: Failed to establish a new connection: [WinError 10061] No connection could be made because the target machine actively refused it)
2025-03-23 20:49:05,502 - elastic_transport.node_pool - INFO - Resurrected node <Urllib3HttpNode(http://localhost:9200)> (force=False)
2025-03-23 20:49:09,594 - elastic_transport.transport - INFO - HEAD http://localhost:9200/ [status:N/A duration:4.092s]
2025-03-23 20:49:09,595 - elastic_transport.node_pool - WARNING - Node <Urllib3HttpNode(http://localhost:9200)> has failed for 4 times in a row, putting on 8 second timeout
2025-03-23 20:49:09,596 - EventCollector - WARNING - Failed to connect to Elasticsearch: Connection error
2025-03-23 20:49:09,596 - EventCollector - INFO - Events will be stored in local file
2025-03-23 20:49:09,600 - AttackDetector - WARNING - Model or scaler files not found, using rule-based detection
2025-03-23 20:49:09,600 - Monitoring - INFO - Starting IoT security monitoring system...
2025-03-23 20:49:11,622 - Monitoring - ERROR - Monitoring failed: 'EventCollector' object has no attribute 'get_alert_stats'
